Workbook

Sheet Summary
A1: U.S. vs E.U. Mould Sourcing — China+1 Comparison
A2: HS 8480, identical 8-supplier basket (Canada, China, Japan, Malaysia, Singapore, Thailand, Taiwan, Vietnam). US=USD/US Census; EU=EUR/Eurostat Comext, EU-27 extra-EU imports.
A4: Headline comparison (share of the 8-supplier basket)
A5: Metric | E5: United States | G5: European Union
A6: China share of basket, 2018 | E6: =INDEX(Raw_US_8partners!$B$2:$Y$9,MATCH("China",Raw_US_8partners!$A$2:$A$9,0),17)/(INDEX(Raw_US_8partners!$B$2:$Y$9,MATCH("Canada",Raw_US_8partners!$A$2:$A$9,0),17)+INDEX(Raw_US_8partners!$B$2:$Y$9,MATCH("China",Raw_US_8partners!$A$2:$A$9,0),17)+INDEX(Raw_US_8partners!$B$2:$Y$9,MATCH("Japan",Raw_US_8partners!$A$2:$A$9,0),17)+INDEX(Raw_US_8partners!$B$2:$Y$9,MATCH("Malaysia",Raw_US_8partners!$A$2:$A$9,0),17)+INDEX(Raw_US_8partners!$B$2:$Y$9,MATCH("Singapore",Raw_US_8partners!$A$2:$A$9,0),17)+INDEX(Raw_US_8partners!$B$2:$Y$9,MATCH("Thailand",Raw_US_8partners!$A$2:$A$9,0),17)+INDEX(Raw_US_8partners!$B$2:$Y$9,MATCH("Taiwan",Raw_US_8partners!$A$2:$A$9,0),17)+INDEX(Raw_US_8partners!$B$2:$Y$9,MATCH("Vietnam",Raw_US_8partners!$A$2:$A$9,0),17)) -> 0.30229939 | G6: =INDEX(Raw_EU_HS8480!$B$2:$Y$9,MATCH("China",Raw_EU_HS8480!$A$2:$A$9,0),17)/(INDEX(Raw_EU_HS8480!$B$2:$Y$9,MATCH("Canada",Raw_EU_HS8480!$A$2:$A$9,0),17)+INDEX(Raw_EU_HS8480!$B$2:$Y$9,MATCH("China",Raw_EU_HS8480!$A$2:$A$9,0),17)+INDEX(Raw_EU_HS8480!$B$2:$Y$9,MATCH("Japan",Raw_EU_HS8480!$A$2:$A$9,0),17)+INDEX(Raw_EU_HS8480!$B$2:$Y$9,MATCH("Malaysia",Raw_EU_HS8480!$A$2:$A$9,0),17)+INDEX(Raw_EU_HS8480!$B$2:$Y$9,MATCH("Singapore",Raw_EU_HS8480!$A$2:$A$9,0),17)+INDEX(Raw_EU_HS8480!$B$2:$Y$9,MATCH("Thailand",Raw_EU_HS8480!$A$2:$A$9,0),17)+INDEX(Raw_EU_HS8480!$B$2:$Y$9,MATCH("Taiwan",Raw_EU_HS8480!$A$2:$A$9,0),17)+INDEX(Raw_EU_HS8480!$B$2:$Y$9,MATCH("Vietnam",Raw_EU_HS8480!$A$2:$A$9,0),17)) -> 0.88305341
A7: China share of basket, 2025 | E7: =INDEX(Raw_US_8partners!$B$2:$Y$9,MATCH("China",Raw_US_8partners!$A$2:$A$9,0),24)/(INDEX(Raw_US_8partners!$B$2:$Y$9,MATCH("Canada",Raw_US_8partners!$A$2:$A$9,0),24)+INDEX(Raw_US_8partners!$B$2:$Y$9,MATCH("China",Raw_US_8partners!$A$2:$A$9,0),24)+INDEX(Raw_US_8partners!$B$2:$Y$9,MATCH("Japan",Raw_US_8partners!$A$2:$A$9,0),24)+INDEX(Raw_US_8partners!$B$2:$Y$9,MATCH("Malaysia",Raw_US_8partners!$A$2:$A$9,0),24)+INDEX(Raw_US_8partners!$B$2:$Y$9,MATCH("Singapore",Raw_US_8partners!$A$2:$A$9,0),24)+INDEX(Raw_US_8partners!$B$2:$Y$9,MATCH("Thailand",Raw_US_8partners!$A$2:$A$9,0),24)+INDEX(Raw_US_8partners!$B$2:$Y$9,MATCH("Taiwan",Raw_US_8partners!$A$2:$A$9,0),24)+INDEX(Raw_US_8partners!$B$2:$Y$9,MATCH("Vietnam",Raw_US_8partners!$A$2:$A$9,0),24)) -> 0.24435421 | G7: =INDEX(Raw_EU_HS8480!$B$2:$Y$9,MATCH("China",Raw_EU_HS8480!$A$2:$A$9,0),24)/(INDEX(Raw_EU_HS8480!$B$2:$Y$9,MATCH("Canada",Raw_EU_HS8480!$A$2:$A$9,0),24)+INDEX(Raw_EU_HS8480!$B$2:$Y$9,MATCH("China",Raw_EU_HS8480!$A$2:$A$9,0),24)+INDEX(Raw_EU_HS8480!$B$2:$Y$9,MATCH("Japan",Raw_EU_HS8480!$A$2:$A$9,0),24)+INDEX(Raw_EU_HS8480!$B$2:$Y$9,MATCH("Malaysia",Raw_EU_HS8480!$A$2:$A$9,0),24)+INDEX(Raw_EU_HS8480!$B$2:$Y$9,MATCH("Singapore",Raw_EU_HS8480!$A$2:$A$9,0),24)+INDEX(Raw_EU_HS8480!$B$2:$Y$9,MATCH("Thailand",Raw_EU_HS8480!$A$2:$A$9,0),24)+INDEX(Raw_EU_HS8480!$B$2:$Y$9,MATCH("Taiwan",Raw_EU_HS8480!$A$2:$A$9,0),24)+INDEX(Raw_EU_HS8480!$B$2:$Y$9,MATCH("Vietnam",Raw_EU_HS8480!$A$2:$A$9,0),24)) -> 0.93637597
A8: China CAGR 2018–2025 | E8: =(INDEX(Raw_US_8partners!$B$2:$Y$9,MATCH("China",Raw_US_8partners!$A$2:$A$9,0),24)/INDEX(Raw_US_8partners!$B$2:$Y$9,MATCH("China",Raw_US_8partners!$A$2:$A$9,0),17))^(1/7)-1 -> -0.072868526 | G8: =(INDEX(Raw_EU_HS8480!$B$2:$Y$9,MATCH("China",Raw_EU_HS8480!$A$2:$A$9,0),24)/INDEX(Raw_EU_HS8480!$B$2:$Y$9,MATCH("China",Raw_EU_HS8480!$A$2:$A$9,0),17))^(1/7)-1 -> 0.045190733
A9: SE Asia (MY+TH+VN) share, 2018 | E9: =(INDEX(Raw_US_8partners!$B$2:$Y$9,MATCH("Malaysia",Raw_US_8partners!$A$2:$A$9,0),17)+INDEX(Raw_US_8partners!$B$2:$Y$9,MATCH("Thailand",Raw_US_8partners!$A$2:$A$9,0),17)+INDEX(Raw_US_8partners!$B$2:$Y$9,MATCH("Vietnam",Raw_US_8partners!$A$2:$A$9,0),17))/(INDEX(Raw_US_8partners!$B$2:$Y$9,MATCH("Canada",Raw_US_8partners!$A$2:$A$9,0),17)+INDEX(Raw_US_8partners!$B$2:$Y$9,MATCH("China",Raw_US_8partners!$A$2:$A$9,0),17)+INDEX(Raw_US_8partners!$B$2:$Y$9,MATCH("Japan",Raw_US_8partners!$A$2:$A$9,0),17)+INDEX(Raw_US_8partners!$B$2:$Y$9,MATCH("Malaysia",Raw_US_8partners!$A$2:$A$9,0),17)+INDEX(Raw_US_8partners!$B$2:$Y$9,MATCH("Singapore",Raw_US_8partners!$A$2:$A$9,0),17)+INDEX(Raw_US_8partners!$B$2:$Y$9,MATCH("Thailand",Raw_US_8partners!$A$2:$A$9,0),17)+INDEX(Raw_US_8partners!$B$2:$Y$9,MATCH("Taiwan",Raw_US_8partners!$A$2:$A$9,0),17)+INDEX(Raw_US_8partners!$B$2:$Y$9,MATCH("Vietnam",Raw_US_8partners!$A$2:$A$9,0),17)) -> 0.0041189649 | G9: =(INDEX(Raw_EU_HS8480!$B$2:$Y$9,MATCH("Malaysia",Raw_EU_HS8480!$A$2:$A$9,0),17)+INDEX(Raw_EU_HS8480!$B$2:$Y$9,MATCH("Thailand",Raw_EU_HS8480!$A$2:$A$9,0),17)+INDEX(Raw_EU_HS8480!$B$2:$Y$9,MATCH("Vietnam",Raw_EU_HS8480!$A$2:$A$9,0),17))/(INDEX(Raw_EU_HS8480!$B$2:$Y$9,MATCH("Canada",Raw_EU_HS8480!$A$2:$A$9,0),17)+INDEX(Raw_EU_HS8480!$B$2:$Y$9,MATCH("China",Raw_EU_HS8480!$A$2:$A$9,0),17)+INDEX(Raw_EU_HS8480!$B$2:$Y$9,MATCH("Japan",Raw_EU_HS8480!$A$2:$A$9,0),17)+INDEX(Raw_EU_HS8480!$B$2:$Y$9,MATCH("Malaysia",Raw_EU_HS8480!$A$2:$A$9,0),17)+INDEX(Raw_EU_HS8480!$B$2:$Y$9,MATCH("Singapore",Raw_EU_HS8480!$A$2:$A$9,0),17)+INDEX(Raw_EU_HS8480!$B$2:$Y$9,MATCH("Thailand",Raw_EU_HS8480!$A$2:$A$9,0),17)+INDEX(Raw_EU_HS8480!$B$2:$Y$9,MATCH("Taiwan",Raw_EU_HS8480!$A$2:$A$9,0),17)+INDEX(Raw_EU_HS8480!$B$2:$Y$9,MATCH("Vietnam",Raw_EU_HS8480!$A$2:$A$9,0),17)) -> 0.022345621
A10: SE Asia (MY+TH+VN) share, 2025 | E10: =(INDEX(Raw_US_8partners!$B$2:$Y$9,MATCH("Malaysia",Raw_US_8partners!$A$2:$A$9,0),24)+INDEX(Raw_US_8partners!$B$2:$Y$9,MATCH("Thailand",Raw_US_8partners!$A$2:$A$9,0),24)+INDEX(Raw_US_8partners!$B$2:$Y$9,MATCH("Vietnam",Raw_US_8partners!$A$2:$A$9,0),24))/(INDEX(Raw_US_8partners!$B$2:$Y$9,MATCH("Canada",Raw_US_8partners!$A$2:$A$9,0),24)+INDEX(Raw_US_8partners!$B$2:$Y$9,MATCH("China",Raw_US_8partners!$A$2:$A$9,0),24)+INDEX(Raw_US_8partners!$B$2:$Y$9,MATCH("Japan",Raw_US_8partners!$A$2:$A$9,0),24)+INDEX(Raw_US_8partners!$B$2:$Y$9,MATCH("Malaysia",Raw_US_8partners!$A$2:$A$9,0),24)+INDEX(Raw_US_8partners!$B$2:$Y$9,MATCH("Singapore",Raw_US_8partners!$A$2:$A$9,0),24)+INDEX(Raw_US_8partners!$B$2:$Y$9,MATCH("Thailand",Raw_US_8partners!$A$2:$A$9,0),24)+INDEX(Raw_US_8partners!$B$2:$Y$9,MATCH("Taiwan",Raw_US_8partners!$A$2:$A$9,0),24)+INDEX(Raw_US_8partners!$B$2:$Y$9,MATCH("Vietnam",Raw_US_8partners!$A$2:$A$9,0),24)) -> 0.043661555 | G10: =(INDEX(Raw_EU_HS8480!$B$2:$Y$9,MATCH("Malaysia",Raw_EU_HS8480!$A$2:$A$9,0),24)+INDEX(Raw_EU_HS8480!$B$2:$Y$9,MATCH("Thailand",Raw_EU_HS8480!$A$2:$A$9,0),24)+INDEX(Raw_EU_HS8480!$B$2:$Y$9,MATCH("Vietnam",Raw_EU_HS8480!$A$2:$A$9,0),24))/(INDEX(Raw_EU_HS8480!$B$2:$Y$9,MATCH("Canada",Raw_EU_HS8480!$A$2:$A$9,0),24)+INDEX(Raw_EU_HS8480!$B$2:$Y$9,MATCH("China",Raw_EU_HS8480!$A$2:$A$9,0),24)+INDEX(Raw_EU_HS8480!$B$2:$Y$9,MATCH("Japan",Raw_EU_HS8480!$A$2:$A$9,0),24)+INDEX(Raw_EU_HS8480!$B$2:$Y$9,MATCH("Malaysia",Raw_EU_HS8480!$A$2:$A$9,0),24)+INDEX(Raw_EU_HS8480!$B$2:$Y$9,MATCH("Singapore",Raw_EU_HS8480!$A$2:$A$9,0),24)+INDEX(Raw_EU_HS8480!$B$2:$Y$9,MATCH("Thailand",Raw_EU_HS8480!$A$2:$A$9,0),24)+INDEX(Raw_EU_HS8480!$B$2:$Y$9,MATCH("Taiwan",Raw_EU_HS8480!$A$2:$A$9,0),24)+INDEX(Raw_EU_HS8480!$B$2:$Y$9,MATCH("Vietnam",Raw_EU_HS8480!$A$2:$A$9,0),24)) -> 0.019693448
A11: SE Asia CAGR 2018–2025 | E11: =((INDEX(Raw_US_8partners!$B$2:$Y$9,MATCH("Malaysia",Raw_US_8partners!$A$2:$A$9,0),24)+INDEX(Raw_US_8partners!$B$2:$Y$9,MATCH("Thailand",Raw_US_8partners!$A$2:$A$9,0),24)+INDEX(Raw_US_8partners!$B$2:$Y$9,MATCH("Vietnam",Raw_US_8partners!$A$2:$A$9,0),24))/(INDEX(Raw_US_8partners!$B$2:$Y$9,MATCH("Malaysia",Raw_US_8partners!$A$2:$A$9,0),17)+INDEX(Raw_US_8partners!$B$2:$Y$9,MATCH("Thailand",Raw_US_8partners!$A$2:$A$9,0),17)+INDEX(Raw_US_8partners!$B$2:$Y$9,MATCH("Vietnam",Raw_US_8partners!$A$2:$A$9,0),17)))^(1/7)-1 -> 0.33911179 | G11: =((INDEX(Raw_EU_HS8480!$B$2:$Y$9,MATCH("Malaysia",Raw_EU_HS8480!$A$2:$A$9,0),24)+INDEX(Raw_EU_HS8480!$B$2:$Y$9,MATCH("Thailand",Raw_EU_HS8480!$A$2:$A$9,0),24)+INDEX(Raw_EU_HS8480!$B$2:$Y$9,MATCH("Vietnam",Raw_EU_HS8480!$A$2:$A$9,0),24))/(INDEX(Raw_EU_HS8480!$B$2:$Y$9,MATCH("Malaysia",Raw_EU_HS8480!$A$2:$A$9,0),17)+INDEX(Raw_EU_HS8480!$B$2:$Y$9,MATCH("Thailand",Raw_EU_HS8480!$A$2:$A$9,0),17)+INDEX(Raw_EU_HS8480!$B$2:$Y$9,MATCH("Vietnam",Raw_EU_HS8480!$A$2:$A$9,0),17)))^(1/7)-1 -> 0.017933184
A12: Basket total, 2025 (native ccy) | E12: =(INDEX(Raw_US_8partners!$B$2:$Y$9,MATCH("Canada",Raw_US_8partners!$A$2:$A$9,0),24)+INDEX(Raw_US_8partners!$B$2:$Y$9,MATCH("China",Raw_US_8partners!$A$2:$A$9,0),24)+INDEX(Raw_US_8partners!$B$2:$Y$9,MATCH("Japan",Raw_US_8partners!$A$2:$A$9,0),24)+INDEX(Raw_US_8partners!$B$2:$Y$9,MATCH("Malaysia",Raw_US_8partners!$A$2:$A$9,0),24)+INDEX(Raw_US_8partners!$B$2:$Y$9,MATCH("Singapore",Raw_US_8partners!$A$2:$A$9,0),24)+INDEX(Raw_US_8partners!$B$2:$Y$9,MATCH("Thailand",Raw_US_8partners!$A$2:$A$9,0),24)+INDEX(Raw_US_8partners!$B$2:$Y$9,MATCH("Taiwan",Raw_US_8partners!$A$2:$A$9,0),24)+INDEX(Raw_US_8partners!$B$2:$Y$9,MATCH("Vietnam",Raw_US_8partners!$A$2:$A$9,0),24)) -> 1443668447 | G12: =(INDEX(Raw_EU_HS8480!$B$2:$Y$9,MATCH("Canada",Raw_EU_HS8480!$A$2:$A$9,0),24)+INDEX(Raw_EU_HS8480!$B$2:$Y$9,MATCH("China",Raw_EU_HS8480!$A$2:$A$9,0),24)+INDEX(Raw_EU_HS8480!$B$2:$Y$9,MATCH("Japan",Raw_EU_HS8480!$A$2:$A$9,0),24)+INDEX(Raw_EU_HS8480!$B$2:$Y$9,MATCH("Malaysia",Raw_EU_HS8480!$A$2:$A$9,0),24)+INDEX(Raw_EU_HS8480!$B$2:$Y$9,MATCH("Singapore",Raw_EU_HS8480!$A$2:$A$9,0),24)+INDEX(Raw_EU_HS8480!$B$2:$Y$9,MATCH("Thailand",Raw_EU_HS8480!$A$2:$A$9,0),24)+INDEX(Raw_EU_HS8480!$B$2:$Y$9,MATCH("Taiwan",Raw_EU_HS8480!$A$2:$A$9,0),24)+INDEX(Raw_EU_HS8480!$B$2:$Y$9,MATCH("Vietnam",Raw_EU_HS8480!$A$2:$A$9,0),24)) -> 1695258152
A13: Imports from China, 2025 (native) | E13: =INDEX(Raw_US_8partners!$B$2:$Y$9,MATCH("China",Raw_US_8partners!$A$2:$A$9,0),24) -> 352766466 | G13: =INDEX(Raw_EU_HS8480!$B$2:$Y$9,MATCH("China",Raw_EU_HS8480!$A$2:$A$9,0),24) -> 1587398991
A15: Key findings
A16: 1. China+1 in moulds is a U.S. phenomenon, not a Western one. On the identical 8-supplier basket, China's share fell in the US (30%→24%, −7.3%/yr) but ROSE in the EU (88%→94%, +4.5%/yr) — China is at a record high into Europe.
A17: 2. The SE-Asia challengers (Malaysia+Thailand+Vietnam) surged in the US (+34%/yr, 0.4%→4.4% of basket) but stayed flat in the EU (~2%). European buyers have not diversified away from China.
A18: 3. Country signs flip: China −7% US / +5% EU; Malaysia +23% US / −9% EU; Thailand +42% US / +10% EU. Only Vietnam grows in BOTH markets (+22% US / +6.5% EU) — the most structurally competitive, least tariff-dependent SE-Asian supplier.
A19: 4. In absolute terms the EU now imports ~4–5× more Chinese mould value than the US (≈€1.59B vs ≈$0.35B), and the gap is still widening — the mirror image of the US, where Chinese buying peaked in 2018.
A20: 5. Read-through: the demand-side pull for China-alternative sourcing exists in the US market today, driven by US-specific trade policy (Section 301 since 2018, Section 232). It is largely absent in the EU. The tailwind is real but policy-contingent, not a universal structural shift.
A21: 6. Strategic implication: anchor the platform on US buyers first (behaviour change already underway); treat the EU as a latent/future market pending EU de-risking or CBAM catalysts. Favour Vietnam (robust in both markets); treat Malaysia's US momentum as more tariff-contingent (it is losing share in the EU).
A22: Scope note: the EU basket excludes intra-EU suppliers (Germany, Italy, Portugal), so '94%' = China's share of EU imports FROM these 8 non-EU countries, not of all EU mould sourcing. Currency differs (USD vs EUR); shares and CAGRs are currency-neutral and drive the comparison.

Sheet US_vs_EU_Comparison
A1: China & SE-Asia share of the 8-supplier basket, by year
A2: All values are live formulas referencing the raw sheets. US = US Census; EU = Eurostat Comext.
A4: Series | B4: 2002 | C4: 2003 | D4: 2004 | E4: 2005 | F4: 2006 | G4: 2007 | H4: 2008 | I4: 2009 | J4: 2010 | K4: 2011 | L4: 2012 | M4: 2013 | N4: 2014 | O4: 2015 | P4: 2016 | Q4: 2017 | R4: 2018 | S4: 2019 | T4: 2020 | U4: 2021 | V4: 2022 | W4: 2023 | X4: 2024 | Y4: 2025
A5: China % of basket — US | B5: =INDEX(Raw_US_8partners!$B$2:$Y$9,MATCH("China",Raw_US_8partners!$A$2:$A$9,0),1)/(INDEX(Raw_US_8partners!$B$2:$Y$9,MATCH("Canada",Raw_US_8partners!$A$2:$A$9,0),1)+INDEX(Raw_US_8partners!$B$2:$Y$9,MATCH("China",Raw_US_8partners!$A$2:$A$9,0),1)+INDEX(Raw_US_8partners!$B$2:$Y$9,MATCH("Japan",Raw_US_8partners!$A$2:$A$9,0),1)+INDEX(Raw_US_8partners!$B$2:$Y$9,MATCH("Malaysia",Raw_US_8partners!$A$2:$A$9,0),1)+INDEX(Raw_US_8partners!$B$2:$Y$9,MATCH("Singapore",Raw_US_8partners!$A$2:$A$9,0),1)+INDEX(Raw_US_8partners!$B$2:$Y$9,MATCH("Thailand",Raw_US_8partners!$A$2:$A$9,0),1)+INDEX(Raw_US_8partners!$B$2:$Y$9,MATCH("Taiwan",Raw_US_8partners!$A$2:$A$9,0),1)+INDEX(Raw_US_8partners!$B$2:$Y$9,MATCH("Vietnam",Raw_US_8partners!$A$2:$A$9,0),1)) -> 0.028363552 | C5: =INDEX(Raw_US_8partners!$B$2:$Y$9,MATCH("China",Raw_US_8partners!$A$2:$A$9,0),2)/(INDEX(Raw_US_8partners!$B$2:$Y$9,MATCH("Canada",Raw_US_8partners!$A$2:$A$9,0),2)+INDEX(Raw_US_8partners!$B$2:$Y$9,MATCH("China",Raw_US_8partners!$A$2:$A$9,0),2)+INDEX(Raw_US_8partners!$B$2:$Y$9,MATCH("Japan",Raw_US_8partners!$A$2:$A$9,0),2)+INDEX(Raw_US_8partners!$B$2:$Y$9,MATCH("Malaysia",Raw_US_8partners!$A$2:$A$9,0),2)+INDEX(Raw_US_8partners!$B$2:$Y$9,MATCH("Singapore",Raw_US_8partners!$A$2:$A$9,0),2)+INDEX(Raw_US_8partners!$B$2:$Y$9,MATCH("Thailand",Raw_US_8partners!$A$2:$A$9,0),2)+INDEX(Raw_US_8partners!$B$2:$Y$9,MATCH("Taiwan",Raw_US_8partners!$A$2:$A$9,0),2)+INDEX(Raw_US_8partners!$B$2:$Y$9,MATCH("Vietnam",Raw_US_8partners!$A$2:$A$9,0),2)) -> 0.03782481 | D5: =INDEX(Raw_US_8partners!$B$2:$Y$9,MATCH("China",Raw_US_8partners!$A$2:$A$9,0),3)/(INDEX(Raw_US_8partners!$B$2:$Y$9,MATCH("Canada",Raw_US_8partners!$A$2:$A$9,0),3)+INDEX(Raw_US_8partners!$B$2:$Y$9,MATCH("China",Raw_US_8partners!$A$2:$A$9,0),3)+INDEX(Raw_US_8partners!$B$2:$Y$9,MATCH("Japan",Raw_US_8partners!$A$2:$A$9,0),3)+INDEX(Raw_US_8partners!$B$2:$Y$9,MATCH("Malaysia",Raw_US_8partners!$A$2:$A$9,0),3)+INDEX(Raw_US_8partners!$B$2:$Y$9,MATCH("Singapore",Raw_US_8partners!$A$2:$A$9,0),3)+INDEX(Raw_US_8partners!$B$2:$Y$9,MATCH("Thailand",Raw_US_8partners!$A$2:$A$9,0),3)+INDEX(Raw_US_8partners!$B$2:$Y$9,MATCH("Taiwan",Raw_US_8partners!$A$2:$A$9,0),3)+INDEX(Raw_US_8partners!$B$2:$Y$9,MATCH("Vietnam",Raw_US_8partners!$A$2:$A$9,0),3)) -> 0.048346944 | E5: =INDEX(Raw_US_8partners!$B$2:$Y$9,MATCH("China",Raw_US_8partners!$A$2:$A$9,0),4)/(INDEX(Raw_US_8partners!$B$2:$Y$9,MATCH("Canada",Raw_US_8partners!$A$2:$A$9,0),4)+INDEX(Raw_US_8partners!$B$2:$Y$9,MATCH("China",Raw_US_8partners!$A$2:$A$9,0),4)+INDEX(Raw_US_8partners!$B$2:$Y$9,MATCH("Japan",Raw_US_8partners!$A$2:$A$9,0),4)+INDEX(Raw_US_8partners!$B$2:$Y$9,MATCH("Malaysia",Raw_US_8partners!$A$2:$A$9,0),4)+INDEX(Raw_US_8partners!$B$2:$Y$9,MATCH("Singapore",Raw_US_8partners!$A$2:$A$9,0),4)+INDEX(Raw_US_8partners!$B$2:$Y$9,MATCH("Thailand",Raw_US_8partners!$A$2:$A$9,0),4)+INDEX(Raw_US_8partners!$B$2:$Y$9,MATCH("Taiwan",Raw_US_8partners!$A$2:$A$9,0),4)+INDEX(Raw_US_8partners!$B$2:$Y$9,MATCH("Vietnam",Raw_US_8partners!$A$2:$A$9,0),4)) -> 0.06658864 | F5: =INDEX(Raw_US_8partners!$B$2:$Y$9,MATCH("China",Raw_US_8partners!$A$2:$A$9,0),5)/(INDEX(Raw_US_8partners!$B$2:$Y$9,MATCH("Canada",Raw_US_8partners!$A$2:$A$9,0),5)+INDEX(Raw_US_8partners!$B$2:$Y$9,MATCH("China",Raw_US_8partners!$A$2:$A$9,0),5)+INDEX(Raw_US_8partners!$B$2:$Y$9,MATCH("Japan",Raw_US_8partners!$A$2:$A$9,0),5)+INDEX(Raw_US_8partners!$B$2:$Y$9,MATCH("Malaysia",Raw_US_8partners!$A$2:$A$9,0),5)+INDEX(Raw_US_8partners!$B$2:$Y$9,MATCH("Singapore",Raw_US_8partners!$A$2:$A$9,0),5)+INDEX(Raw_US_8partners!$B$2:$Y$9,MATCH("Thailand",Raw_US_8partners!$A$2:$A$9,0),5)+INDEX(Raw_US_8partners!$B$2:$Y$9,MATCH("Taiwan",Raw_US_8partners!$A$2:$A$9,0),5)+INDEX(Raw_US_8partners!$B$2:$Y$9,MATCH("Vietnam",Raw_US_8partners!$A$2:$A$9,0),5)) -> 0.089614181 | G5: =INDEX(Raw_US_8partners!$B$2:$Y$9,MATCH("China",Raw_US_8partners!$A$2:$A$9,0),6)/(INDEX(Raw_US_8partners!$B$2:$Y$9,MATCH("Canada",Raw_US_8partners!$A$2:$A$9,0),6)+INDEX(Raw_US_8partners!$B$2:$Y$9,MATCH("China",Raw_US_8partners!$A$2:$A$9,0),6)+INDEX(Raw_US_8partners!$B$2:$Y$9,MATCH("Japan",Raw_US_8partners!$A$2:$A$9,0),6)+INDEX(Raw_US_8partners!$B$2:$Y$9,MATCH("Malaysia",Raw_US_8partners!$A$2:$A$9,0),6)+INDEX(Raw_US_8partners!$B$2:$Y$9,MATCH("Singapore",Raw_US_8partners!$A$2:$A$9,0),6)+INDEX(Raw_US_8partners!$B$2:$Y$9,MATCH("Thailand",Raw_US_8partners!$A$2:$A$9,0),6)+INDEX(Raw_US_8partners!$B$2:$Y$9,MATCH("Taiwan",Raw_US_8partners!$A$2:$A$9,0),6)+INDEX(Raw_US_8partners!$B$2:$Y$9,MATCH("Vietnam",Raw_US_8partners!$A$2:$A$9,0),6)) -> 0.14211843 | H5: =INDEX(Raw_US_8partners!$B$2:$Y$9,MATCH("China",Raw_US_8partners!$A$2:$A$9,0),7)/(INDEX(Raw_US_8partners!$B$2:$Y$9,MATCH("Canada",Raw_US_8partners!$A$2:$A$9,0),7)+INDEX(Raw_US_8partners!$B$2:$Y$9,MATCH("China",Raw_US_8partners!$A$2:$A$9,0),7)+INDEX(Raw_US_8partners!$B$2:$Y$9,MATCH("Japan",Raw_US_8partners!$A$2:$A$9,0),7)+INDEX(Raw_US_8partners!$B$2:$Y$9,MATCH("Malaysia",Raw_US_8partners!$A$2:$A$9,0),7)+INDEX(Raw_US_8partners!$B$2:$Y$9,MATCH("Singapore",Raw_US_8partners!$A$2:$A$9,0),7)+INDEX(Raw_US_8partners!$B$2:$Y$9,MATCH("Thailand",Raw_US_8partners!$A$2:$A$9,0),7)+INDEX(Raw_US_8partners!$B$2:$Y$9,MATCH("Taiwan",Raw_US_8partners!$A$2:$A$9,0),7)+INDEX(Raw_US_8partners!$B$2:$Y$9,MATCH("Vietnam",Raw_US_8partners!$A$2:$A$9,0),7)) -> 0.16061663 | I5: =INDEX(Raw_US_8partners!$B$2:$Y$9,MATCH("China",Raw_US_8partners!$A$2:$A$9,0),8)/(INDEX(Raw_US_8partners!$B$2:$Y$9,MATCH("Canada",Raw_US_8partners!$A$2:$A$9,0),8)+INDEX(Raw_US_8partners!$B$2:$Y$9,MATCH("China",Raw_US_8partners!$A$2:$A$9,0),8)+INDEX(Raw_US_8partners!$B$2:$Y$9,MATCH("Japan",Raw_US_8partners!$A$2:$A$9,0),8)+INDEX(Raw_US_8partners!$B$2:$Y$9,MATCH("Malaysia",Raw_US_8partners!$A$2:$A$9,0),8)+INDEX(Raw_US_8partners!$B$2:$Y$9,MATCH("Singapore",Raw_US_8partners!$A$2:$A$9,0),8)+INDEX(Raw_US_8partners!$B$2:$Y$9,MATCH("Thailand",Raw_US_8partners!$A$2:$A$9,0),8)+INDEX(Raw_US_8partners!$B$2:$Y$9,MATCH("Taiwan",Raw_US_8partners!$A$2:$A$9,0),8)+INDEX(Raw_US_8partners!$B$2:$Y$9,MATCH("Vietnam",Raw_US_8partners!$A$2:$A$9,0),8)) -> 0.18561031 | J5: =INDEX(Raw_US_8partners!$B$2:$Y$9,MATCH("China",Raw_US_8partners!$A$2:$A$9,0),9)/(INDEX(Raw_US_8partners!$B$2:$Y$9,MATCH("Canada",Raw_US_8partners!$A$2:$A$9,0),9)+INDEX(Raw_US_8partners!$B$2:$Y$9,MATCH("China",Raw_US_8partners!$A$2:$A$9,0),9)+INDEX(Raw_US_8partners!$B$2:$Y$9,MATCH("Japan",Raw_US_8partners!$A$2:$A$9,0),9)+INDEX(Raw_US_8partners!$B$2:$Y$9,MATCH("Malaysia",Raw_US_8partners!$A$2:$A$9,0),9)+INDEX(Raw_US_8partners!$B$2:$Y$9,MATCH("Singapore",Raw_US_8partners!$A$2:$A$9,0),9)+INDEX(Raw_US_8partners!$B$2:$Y$9,MATCH("Thailand",Raw_US_8partners!$A$2:$A$9,0),9)+INDEX(Raw_US_8partners!$B$2:$Y$9,MATCH("Taiwan",Raw_US_8partners!$A$2:$A$9,0),9)+INDEX(Raw_US_8partners!$B$2:$Y$9,MATCH("Vietnam",Raw_US_8partners!$A$2:$A$9,0),9)) -> 0.22401012 | K5: =INDEX(Raw_US_8partners!$B$2:$Y$9,MATCH("China",Raw_US_8partners!$A$2:$A$9,0),10)/(INDEX(Raw_US_8partners!$B$2:$Y$9,MATCH("Canada",Raw_US_8partners!$A$2:$A$9,0),10)+INDEX(Raw_US_8partners!$B$2:$Y$9,MATCH("China",Raw_US_8partners!$A$2:$A$9,0),10)+INDEX(Raw_US_8partners!$B$2:$Y$9,MATCH("Japan",Raw_US_8partners!$A$2:$A$9,0),10)+INDEX(Raw_US_8partners!$B$2:$Y$9,MATCH("Malaysia",Raw_US_8partners!$A$2:$A$9,0),10)+INDEX(Raw_US_8partners!$B$2:$Y$9,MATCH("Singapore",Raw_US_8partners!$A$2:$A$9,0),10)+INDEX(Raw_US_8partners!$B$2:$Y$9,MATCH("Thailand",Raw_US_8partners!$A$2:$A$9,0),10)+INDEX(Raw_US_8partners!$B$2:$Y$9,MATCH("Taiwan",Raw_US_8partners!$A$2:$A$9,0),10)+INDEX(Raw_US_8partners!$B$2:$Y$9,MATCH("Vietnam",Raw_US_8partners!$A$2:$A$9,0),10)) -> 0.25647937 | L5: =INDEX(Raw_US_8partners!$B$2:$Y$9,MATCH("China",Raw_US_8partners!$A$2:$A$9,0),11)/(INDEX(Raw_US_8partners!$B$2:$Y$9,MATCH("Canada",Raw_US_8partners!$A$2:$A$9,0),11)+INDEX(Raw_US_8partners!$B$2:$Y$9,MATCH("China",Raw_US_8partners!$A$2:$A$9,0),11)+INDEX(Raw_US_8partners!$B$2:$Y$9,MATCH("Japan",Raw_US_8partners!$A$2:$A$9,0),11)+INDEX(Raw_US_8partners!$B$2:$Y$9,MATCH("Malaysia",Raw_US_8partners!$A$2:$A$9,0),11)+INDEX(Raw_US_8partners!$B$2:$Y$9,MATCH("Singapore",Raw_US_8partners!$A$2:$A$9,0),11)+INDEX(Raw_US_8partners!$B$2:$Y$9,MATCH("Thailand",Raw_US_8partners!$A$2:$A$9,0),11)+INDEX(Raw_US_8partners!$B$2:$Y$9,MATCH("Taiwan",Raw_US_8partners!$A$2:$A$9,0),11)+INDEX(Raw_US_8partners!$B$2:$Y$9,MATCH("Vietnam",Raw_US_8partners!$A$2:$A$9,0),11)) -> 0.27285783 | M5: =INDEX(Raw_US_8partners!$B$2:$Y$9,MATCH("China",Raw_US_8partners!$A$2:$A$9,0),12)/(INDEX(Raw_US_8partners!$B$2:$Y$9,MATCH("Canada",Raw_US_8partners!$A$2:$A$9,0),12)+INDEX(Raw_US_8partners!$B$2:$Y$9,MATCH("China",Raw_US_8partners!$A$2:$A$9,0),12)+INDEX(Raw_US_8partners!$B$2:$Y$9,MATCH("Japan",Raw_US_8partners!$A$2:$A$9,0),12)+INDEX(Raw_US_8partners!$B$2:$Y$9,MATCH("Malaysia",Raw_US_8partners!$A$2:$A$9,0),12)+INDEX(Raw_US_8partners!$B$2:$Y$9,MATCH("Singapore",Raw_US_8partners!$A$2:$A$9,0),12)+INDEX(Raw_US_8partners!$B$2:$Y$9,MATCH("Thailand",Raw_US_8partners!$A$2:$A$9,0),12)+INDEX(Raw_US_8partners!$B$2:$Y$9,MATCH("Taiwan",Raw_US_8partners!$A$2:$A$9,0),12)+INDEX(Raw_US_8partners!$B$2:$Y$9,MATCH("Vietnam",Raw_US_8partners!$A$2:$A$9,0),12)) -> 0.26367397 | N5: =INDEX(Raw_US_8partners!$B$2:$Y$9,MATCH("China",Raw_US_8partners!$A$2:$A$9,0),13)/(INDEX(Raw_US_8partners!$B$2:$Y$9,MATCH("Canada",Raw_US_8partners!$A$2:$A$9,0),13)+INDEX(Raw_US_8partners!$B$2:$Y$9,MATCH("China",Raw_US_8partners!$A$2:$A$9,0),13)+INDEX(Raw_US_8partners!$B$2:$Y$9,MATCH("Japan",Raw_US_8partners!$A$2:$A$9,0),13)+INDEX(Raw_US_8partners!$B$2:$Y$9,MATCH("Malaysia",Raw_US_8partners!$A$2:$A$9,0),13)+INDEX(Raw_US_8partners!$B$2:$Y$9,MATCH("Singapore",Raw_US_8partners!$A$2:$A$9,0),13)+INDEX(Raw_US_8partners!$B$2:$Y$9,MATCH("Thailand",Raw_US_8partners!$A$2:$A$9,0),13)+INDEX(Raw_US_8partners!$B$2:$Y$9,MATCH("Taiwan",Raw_US_8partners!$A$2:$A$9,0),13)+INDEX(Raw_US_8partners!$B$2:$Y$9,MATCH("Vietnam",Raw_US_8partners!$A$2:$A$9,0),13)) -> 0.27921638 | O5: =INDEX(Raw_US_8partners!$B$2:$Y$9,MATCH("China",Raw_US_8partners!$A$2:$A$9,0),14)/(INDEX(Raw_US_8partners!$B$2:$Y$9,MATCH("Canada",Raw_US_8partners!$A$2:$A$9,0),14)+INDEX(Raw_US_8partners!$B$2:$Y$9,MATCH("China",Raw_US_8partners!$A$2:$A$9,0),14)+INDEX(Raw_US_8partners!$B$2:$Y$9,MATCH("Japan",Raw_US_8partners!$A$2:$A$9,0),14)+INDEX(Raw_US_8partners!$B$2:$Y$9,MATCH("Malaysia",Raw_US_8partners!$A$2:$A$9,0),14)+INDEX(Raw_US_8partners!$B$2:$Y$9,MATCH("Singapore",Raw_US_8partners!$A$2:$A$9,0),14)+INDEX(Raw_US_8partners!$B$2:$Y$9,MATCH("Thailand",Raw_US_8partners!$A$2:$A$9,0),14)+INDEX(Raw_US_8partners!$B$2:$Y$9,MATCH("Taiwan",Raw_US_8partners!$A$2:$A$9,0),14)+INDEX(Raw_US_8partners!$B$2:$Y$9,MATCH("Vietnam",Raw_US_8partners!$A$2:$A$9,0),14)) -> 0.29825859 | P5: =INDEX(Raw_US_8partners!$B$2:$Y$9,MATCH("China",Raw_US_8partners!$A$2:$A$9,0),15)/(INDEX(Raw_US_8partners!$B$2:$Y$9,MATCH("Canada",Raw_US_8partners!$A$2:$A$9,0),15)+INDEX(Raw_US_8partners!$B$2:$Y$9,MATCH("China",Raw_US_8partners!$A$2:$A$9,0),15)+INDEX(Raw_US_8partners!$B$2:$Y$9,MATCH("Japan",Raw_US_8partners!$A$2:$A$9,0),15)+INDEX(Raw_US_8partners!$B$2:$Y$9,MATCH("Malaysia",Raw_US_8partners!$A$2:$A$9,0),15)+INDEX(Raw_US_8partners!$B$2:$Y$9,MATCH("Singapore",Raw_US_8partners!$A$2:$A$9,0),15)+INDEX(Raw_US_8partners!$B$2:$Y$9,MATCH("Thailand",Raw_US_8partners!$A$2:$A$9,0),15)+INDEX(Raw_US_8partners!$B$2:$Y$9,MATCH("Taiwan",Raw_US_8partners!$A$2:$A$9,0),15)+INDEX(Raw_US_8partners!$B$2:$Y$9,MATCH("Vietnam",Raw_US_8partners!$A$2:$A$9,0),15)) -> 0.27653697 | Q5: =INDEX(Raw_US_8partners!$B$2:$Y$9,MATCH("China",Raw_US_8partners!$A$2:$A$9,0),16)/(INDEX(Raw_US_8partners!$B$2:$Y$9,MATCH("Canada",Raw_US_8partners!$A$2:$A$9,0),16)+INDEX(Raw_US_8partners!$B$2:$Y$9,MATCH("China",Raw_US_8partners!$A$2:$A$9,0),16)+INDEX(Raw_US_8partners!$B$2:$Y$9,MATCH("Japan",Raw_US_8partners!$A$2:$A$9,0),16)+INDEX(Raw_US_8partners!$B$2:$Y$9,MATCH("Malaysia",Raw_US_8partners!$A$2:$A$9,0),16)+INDEX(Raw_US_8partners!$B$2:$Y$9,MATCH("Singapore",Raw_US_8partners!$A$2:$A$9,0),16)+INDEX(Raw_US_8partners!$B$2:$Y$9,MATCH("Thailand",Raw_US_8partners!$A$2:$A$9,0),16)+INDEX(Raw_US_8partners!$B$2:$Y$9,MATCH("Taiwan",Raw_US_8partners!$A$2:$A$9,0),16)+INDEX(Raw_US_8partners!$B$2:$Y$9,MATCH("Vietnam",Raw_US_8partners!$A$2:$A$9,0),16)) -> 0.29625189 | R5: =INDEX(Raw_US_8partners!$B$2:$Y$9,MATCH("China",Raw_US_8partners!$A$2:$A$9,0),17)/(INDEX(Raw_US_8partners!$B$2:$Y$9,MATCH("Canada",Raw_US_8partners!$A$2:$A$9,0),17)+INDEX(Raw_US_8partners!$B$2:$Y$9,MATCH("China",Raw_US_8partners!$A$2:$A$9,0),17)+INDEX(Raw_US_8partners!$B$2:$Y$9,MATCH("Japan",Raw_US_8partners!$A$2:$A$9,0),17)+INDEX(Raw_US_8partners!$B$2:$Y$9,MATCH("Malaysia",Raw_US_8partners!$A$2:$A$9,0),17)+INDEX(Raw_US_8partners!$B$2:$Y$9,MATCH("Singapore",Raw_US_8partners!$A$2:$A$9,0),17)+INDEX(Raw_US_8partners!$B$2:$Y$9,MATCH("Thailand",Raw_US_8partners!$A$2:$A$9,0),17)+INDEX(Raw_US_8partners!$B$2:$Y$9,MATCH("Taiwan",Raw_US_8partners!$A$2:$A$9,0),17)+INDEX(Raw_US_8partners!$B$2:$Y$9,MATCH("Vietnam",Raw_US_8partners!$A$2:$A$9,0),17)) -> 0.30229939 | S5: =INDEX(Raw_US_8partners!$B$2:$Y$9,MATCH("China",Raw_US_8partners!$A$2:$A$9,0),18)/(INDEX(Raw_US_8partners!$B$2:$Y$9,MATCH("Canada",Raw_US_8partners!$A$2:$A$9,0),18)+INDEX(Raw_US_8partners!$B$2:$Y$9,MATCH("China",Raw_US_8partners!$A$2:$A$9,0),18)+INDEX(Raw_US_8partners!$B$2:$Y$9,MATCH("Japan",Raw_US_8partners!$A$2:$A$9,0),18)+INDEX(Raw_US_8partners!$B$2:$Y$9,MATCH("Malaysia",Raw_US_8partners!$A$2:$A$9,0),18)+INDEX(Raw_US_8partners!$B$2:$Y$9,MATCH("Singapore",Raw_US_8partners!$A$2:$A$9,0),18)+INDEX(Raw_US_8partners!$B$2:$Y$9,MATCH("Thailand",Raw_US_8partners!$A$2:$A$9,0),18)+INDEX(Raw_US_8partners!$B$2:$Y$9,MATCH("Taiwan",Raw_US_8partners!$A$2:$A$9,0),18)+INDEX(Raw_US_8partners!$B$2:$Y$9,MATCH("Vietnam",Raw_US_8partners!$A$2:$A$9,0),18)) -> 0.29168691 | T5: =INDEX(Raw_US_8partners!$B$2:$Y$9,MATCH("China",Raw_US_8partners!$A$2:$A$9,0),19)/(INDEX(Raw_US_8partners!$B$2:$Y$9,MATCH("Canada",Raw_US_8partners!$A$2:$A$9,0),19)+INDEX(Raw_US_8partners!$B$2:$Y$9,MATCH("China",Raw_US_8partners!$A$2:$A$9,0),19)+INDEX(Raw_US_8partners!$B$2:$Y$9,MATCH("Japan",Raw_US_8partners!$A$2:$A$9,0),19)+INDEX(Raw_US_8partners!$B$2:$Y$9,MATCH("Malaysia",Raw_US_8partners!$A$2:$A$9,0),19)+INDEX(Raw_US_8partners!$B$2:$Y$9,MATCH("Singapore",Raw_US_8partners!$A$2:$A$9,0),19)+INDEX(Raw_US_8partners!$B$2:$Y$9,MATCH("Thailand",Raw_US_8partners!$A$2:$A$9,0),19)+INDEX(Raw_US_8partners!$B$2:$Y$9,MATCH("Taiwan",Raw_US_8partners!$A$2:$A$9,0),19)+INDEX(Raw_US_8partners!$B$2:$Y$9,MATCH("Vietnam",Raw_US_8partners!$A$2:$A$9,0),19)) -> 0.26952113 | U5: =INDEX(Raw_US_8partners!$B$2:$Y$9,MATCH("China",Raw_US_8partners!$A$2:$A$9,0),20)/(INDEX(Raw_US_8partners!$B$2:$Y$9,MATCH("Canada",Raw_US_8partners!$A$2:$A$9,0),20)+INDEX(Raw_US_8partners!$B$2:$Y$9,MATCH("China",Raw_US_8partners!$A$2:$A$9,0),20)+INDEX(Raw_US_8partners!$B$2:$Y$9,MATCH("Japan",Raw_US_8partners!$A$2:$A$9,0),20)+INDEX(Raw_US_8partners!$B$2:$Y$9,MATCH("Malaysia",Raw_US_8partners!$A$2:$A$9,0),20)+INDEX(Raw_US_8partners!$B$2:$Y$9,MATCH("Singapore",Raw_US_8partners!$A$2:$A$9,0),20)+INDEX(Raw_US_8partners!$B$2:$Y$9,MATCH("Thailand",Raw_US_8partners!$A$2:$A$9,0),20)+INDEX(Raw_US_8partners!$B$2:$Y$9,MATCH("Taiwan",Raw_US_8partners!$A$2:$A$9,0),20)+INDEX(Raw_US_8partners!$B$2:$Y$9,MATCH("Vietnam",Raw_US_8partners!$A$2:$A$9,0),20)) -> 0.25753441 | V5: =INDEX(Raw_US_8partners!$B$2:$Y$9,MATCH("China",Raw_US_8partners!$A$2:$A$9,0),21)/(INDEX(Raw_US_8partners!$B$2:$Y$9,MATCH("Canada",Raw_US_8partners!$A$2:$A$9,0),21)+INDEX(Raw_US_8partners!$B$2:$Y$9,MATCH("China",Raw_US_8partners!$A$2:$A$9,0),21)+INDEX(Raw_US_8partners!$B$2:$Y$9,MATCH("Japan",Raw_US_8partners!$A$2:$A$9,0),21)+INDEX(Raw_US_8partners!$B$2:$Y$9,MATCH("Malaysia",Raw_US_8partners!$A$2:$A$9,0),21)+INDEX(Raw_US_8partners!$B$2:$Y$9,MATCH("Singapore",Raw_US_8partners!$A$2:$A$9,0),21)+INDEX(Raw_US_8partners!$B$2:$Y$9,MATCH("Thailand",Raw_US_8partners!$A$2:$A$9,0),21)+INDEX(Raw_US_8partners!$B$2:$Y$9,MATCH("Taiwan",Raw_US_8partners!$A$2:$A$9,0),21)+INDEX(Raw_US_8partners!$B$2:$Y$9,MATCH("Vietnam",Raw_US_8partners!$A$2:$A$9,0),21)) -> 0.24422588 | W5: =INDEX(Raw_US_8partners!$B$2:$Y$9,MATCH("China",Raw_US_8partners!$A$2:$A$9,0),22)/(INDEX(Raw_US_8partners!$B$2:$Y$9,MATCH("Canada",Raw_US_8partners!$A$2:$A$9,0),22)+INDEX(Raw_US_8partners!$B$2:$Y$9,MATCH("China",Raw_US_8partners!$A$2:$A$9,0),22)+INDEX(Raw_US_8partners!$B$2:$Y$9,MATCH("Japan",Raw_US_8partners!$A$2:$A$9,0),22)+INDEX(Raw_US_8partners!$B$2:$Y$9,MATCH("Malaysia",Raw_US_8partners!$A$2:$A$9,0),22)+INDEX(Raw_US_8partners!$B$2:$Y$9,MATCH("Singapore",Raw_US_8partners!$A$2:$A$9,0),22)+INDEX(Raw_US_8partners!$B$2:$Y$9,MATCH("Thailand",Raw_US_8partners!$A$2:$A$9,0),22)+INDEX(Raw_US_8partners!$B$2:$Y$9,MATCH("Taiwan",Raw_US_8partners!$A$2:$A$9,0),22)+INDEX(Raw_US_8partners!$B$2:$Y$9,MATCH("Vietnam",Raw_US_8partners!$A$2:$A$9,0),22)) -> 0.23059029 | X5: =INDEX(Raw_US_8partners!$B$2:$Y$9,MATCH("China",Raw_US_8partners!$A$2:$A$9,0),23)/(INDEX(Raw_US_8partners!$B$2:$Y$9,MATCH("Canada",Raw_US_8partners!$A$2:$A$9,0),23)+INDEX(Raw_US_8partners!$B$2:$Y$9,MATCH("China",Raw_US_8partners!$A$2:$A$9,0),23)+INDEX(Raw_US_8partners!$B$2:$Y$9,MATCH("Japan",Raw_US_8partners!$A$2:$A$9,0),23)+INDEX(Raw_US_8partners!$B$2:$Y$9,MATCH("Malaysia",Raw_US_8partners!$A$2:$A$9,0),23)+INDEX(Raw_US_8partners!$B$2:$Y$9,MATCH("Singapore",Raw_US_8partners!$A$2:$A$9,0),23)+INDEX(Raw_US_8partners!$B$2:$Y$9,MATCH("Thailand",Raw_US_8partners!$A$2:$A$9,0),23)+INDEX(Raw_US_8partners!$B$2:$Y$9,MATCH("Taiwan",Raw_US_8partners!$A$2:$A$9,0),23)+INDEX(Raw_US_8partners!$B$2:$Y$9,MATCH("Vietnam",Raw_US_8partners!$A$2:$A$9,0),23)) -> 0.24908922 | Y5: =INDEX(Raw_US_8partners!$B$2:$Y$9,MATCH("China",Raw_US_8partners!$A$2:$A$9,0),24)/(INDEX(Raw_US_8partners!$B$2:$Y$9,MATCH("Canada",Raw_US_8partners!$A$2:$A$9,0),24)+INDEX(Raw_US_8partners!$B$2:$Y$9,MATCH("China",Raw_US_8partners!$A$2:$A$9,0),24)+INDEX(Raw_US_8partners!$B$2:$Y$9,MATCH("Japan",Raw_US_8partners!$A$2:$A$9,0),24)+INDEX(Raw_US_8partners!$B$2:$Y$9,MATCH("Malaysia",Raw_US_8partners!$A$2:$A$9,0),24)+INDEX(Raw_US_8partners!$B$2:$Y$9,MATCH("Singapore",Raw_US_8partners!$A$2:$A$9,0),24)+INDEX(Raw_US_8partners!$B$2:$Y$9,MATCH("Thailand",Raw_US_8partners!$A$2:$A$9,0),24)+INDEX(Raw_US_8partners!$B$2:$Y$9,MATCH("Taiwan",Raw_US_8partners!$A$2:$A$9,0),24)+INDEX(Raw_US_8partners!$B$2:$Y$9,MATCH("Vietnam",Raw_US_8partners!$A$2:$A$9,0),24)) -> 0.24435421
A6: China % of basket — EU | B6: =INDEX(Raw_EU_HS8480!$B$2:$Y$9,MATCH("China",Raw_EU_HS8480!$A$2:$A$9,0),1)/(INDEX(Raw_EU_HS8480!$B$2:$Y$9,MATCH("Canada",Raw_EU_HS8480!$A$2:$A$9,0),1)+INDEX(Raw_EU_HS8480!$B$2:$Y$9,MATCH("China",Raw_EU_HS8480!$A$2:$A$9,0),1)+INDEX(Raw_EU_HS8480!$B$2:$Y$9,MATCH("Japan",Raw_EU_HS8480!$A$2:$A$9,0),1)+INDEX(Raw_EU_HS8480!$B$2:$Y$9,MATCH("Malaysia",Raw_EU_HS8480!$A$2:$A$9,0),1)+INDEX(Raw_EU_HS8480!$B$2:$Y$9,MATCH("Singapore",Raw_EU_HS8480!$A$2:$A$9,0),1)+INDEX(Raw_EU_HS8480!$B$2:$Y$9,MATCH("Thailand",Raw_EU_HS8480!$A$2:$A$9,0),1)+INDEX(Raw_EU_HS8480!$B$2:$Y$9,MATCH("Taiwan",Raw_EU_HS8480!$A$2:$A$9,0),1)+INDEX(Raw_EU_HS8480!$B$2:$Y$9,MATCH("Vietnam",Raw_EU_HS8480!$A$2:$A$9,0),1)) -> 0.20434125 | C6: =INDEX(Raw_EU_HS8480!$B$2:$Y$9,MATCH("China",Raw_EU_HS8480!$A$2:$A$9,0),2)/(INDEX(Raw_EU_HS8480!$B$2:$Y$9,MATCH("Canada",Raw_EU_HS8480!$A$2:$A$9,0),2)+INDEX(Raw_EU_HS8480!$B$2:$Y$9,MATCH("China",Raw_EU_HS8480!$A$2:$A$9,0),2)+INDEX(Raw_EU_HS8480!$B$2:$Y$9,MATCH("Japan",Raw_EU_HS8480!$A$2:$A$9,0),2)+INDEX(Raw_EU_HS8480!$B$2:$Y$9,MATCH("Malaysia",Raw_EU_HS8480!$A$2:$A$9,0),2)+INDEX(Raw_EU_HS8480!$B$2:$Y$9,MATCH("Singapore",Raw_EU_HS8480!$A$2:$A$9,0),2)+INDEX(Raw_EU_HS8480!$B$2:$Y$9,MATCH("Thailand",Raw_EU_HS8480!$A$2:$A$9,0),2)+INDEX(Raw_EU_HS8480!$B$2:$Y$9,MATCH("Taiwan",Raw_EU_HS8480!$A$2:$A$9,0),2)+INDEX(Raw_EU_HS8480!$B$2:$Y$9,MATCH("Vietnam",Raw_EU_HS8480!$A$2:$A$9,0),2)) -> 0.23998702 | D6: =INDEX(Raw_EU_HS8480!$B$2:$Y$9,MATCH("China",Raw_EU_HS8480!$A$2:$A$9,0),3)/(INDEX(Raw_EU_HS8480!$B$2:$Y$9,MATCH("Canada",Raw_EU_HS8480!$A$2:$A$9,0),3)+INDEX(Raw_EU_HS8480!$B$2:$Y$9,MATCH("China",Raw_EU_HS8480!$A$2:$A$9,0),3)+INDEX(Raw_EU_HS8480!$B$2:$Y$9,MATCH("Japan",Raw_EU_HS8480!$A$2:$A$9,0),3)+INDEX(Raw_EU_HS8480!$B$2:$Y$9,MATCH("Malaysia",Raw_EU_HS8480!$A$2:$A$9,0),3)+INDEX(Raw_EU_HS8480!$B$2:$Y$9,MATCH("Singapore",Raw_EU_HS8480!$A$2:$A$9,0),3)+INDEX(Raw_EU_HS8480!$B$2:$Y$9,MATCH("Thailand",Raw_EU_HS8480!$A$2:$A$9,0),3)+INDEX(Raw_EU_HS8480!$B$2:$Y$9,MATCH("Taiwan",Raw_EU_HS8480!$A$2:$A$9,0),3)+INDEX(Raw_EU_HS8480!$B$2:$Y$9,MATCH("Vietnam",Raw_EU_HS8480!$A$2:$A$9,0),3)) -> 0.33579422 | E6: =INDEX(Raw_EU_HS8480!$B$2:$Y$9,MATCH("China",Raw_EU_HS8480!$A$2:$A$9,0),4)/(INDEX(Raw_EU_HS8480!$B$2:$Y$9,MATCH("Canada",Raw_EU_HS8480!$A$2:$A$9,0),4)+INDEX(Raw_EU_HS8480!$B$2:$Y$9,MATCH("China",Raw_EU_HS8480!$A$2:$A$9,0),4)+INDEX(Raw_EU_HS8480!$B$2:$Y$9,MATCH("Japan",Raw_EU_HS8480!$A$2:$A$9,0),4)+INDEX(Raw_EU_HS8480!$B$2:$Y$9,MATCH("Malaysia",Raw_EU_HS8480!$A$2:$A$9,0),4)+INDEX(Raw_EU_HS8480!$B$2:$Y$9,MATCH("Singapore",Raw_EU_HS8480!$A$2:$A$9,0),4)+INDEX(Raw_EU_HS8480!$B$2:$Y$9,MATCH("Thailand",Raw_EU_HS8480!$A$2:$A$9,0),4)+INDEX(Raw_EU_HS8480!$B$2:$Y$9,MATCH("Taiwan",Raw_EU_HS8480!$A$2:$A$9,0),4)+INDEX(Raw_EU_HS8480!$B$2:$Y$9,MATCH("Vietnam",Raw_EU_HS8480!$A$2:$A$9,0),4)) -> 0.44753642 | F6: =INDEX(Raw_EU_HS8480!$B$2:$Y$9,MATCH("China",Raw_EU_HS8480!$A$2:$A$9,0),5)/(INDEX(Raw_EU_HS8480!$B$2:$Y$9,MATCH("Canada",Raw_EU_HS8480!$A$2:$A$9,0),5)+INDEX(Raw_EU_HS8480!$B$2:$Y$9,MATCH("China",Raw_EU_HS8480!$A$2:$A$9,0),5)+INDEX(Raw_EU_HS8480!$B$2:$Y$9,MATCH("Japan",Raw_EU_HS8480!$A$2:$A$9,0),5)+INDEX(Raw_EU_HS8480!$B$2:$Y$9,MATCH("Malaysia",Raw_EU_HS8480!$A$2:$A$9,0),5)+INDEX(Raw_EU_HS8480!$B$2:$Y$9,MATCH("Singapore",Raw_EU_HS8480!$A$2:$A$9,0),5)+INDEX(Raw_EU_HS8480!$B$2:$Y$9,MATCH("Thailand",Raw_EU_HS8480!$A$2:$A$9,0),5)+INDEX(Raw_EU_HS8480!$B$2:$Y$9,MATCH("Taiwan",Raw_EU_HS8480!$A$2:$A$9,0),5)+INDEX(Raw_EU_HS8480!$B$2:$Y$9,MATCH("Vietnam",Raw_EU_HS8480!$A$2:$A$9,0),5)) -> 0.52896218 | G6: =INDEX(Raw_EU_HS8480!$B$2:$Y$9,MATCH("China",Raw_EU_HS8480!$A$2:$A$9,0),6)/(INDEX(Raw_EU_HS8480!$B$2:$Y$9,MATCH("Canada",Raw_EU_HS8480!$A$2:$A$9,0),6)+INDEX(Raw_EU_HS8480!$B$2:$Y$9,MATCH("China",Raw_EU_HS8480!$A$2:$A$9,0),6)+INDEX(Raw_EU_HS8480!$B$2:$Y$9,MATCH("Japan",Raw_EU_HS8480!$A$2:$A$9,0),6)+INDEX(Raw_EU_HS8480!$B$2:$Y$9,MATCH("Malaysia",Raw_EU_HS8480!$A$2:$A$9,0),6)+INDEX(Raw_EU_HS8480!$B$2:$Y$9,MATCH("Singapore",Raw_EU_HS8480!$A$2:$A$9,0),6)+INDEX(Raw_EU_HS8480!$B$2:$Y$9,MATCH("Thailand",Raw_EU_HS8480!$A$2:$A$9,0),6)+INDEX(Raw_EU_HS8480!$B$2:$Y$9,MATCH("Taiwan",Raw_EU_HS8480!$A$2:$A$9,0),6)+INDEX(Raw_EU_HS8480!$B$2:$Y$9,MATCH("Vietnam",Raw_EU_HS8480!$A$2:$A$9,0),6)) -> 0.59851864 | H6: =INDEX(Raw_EU_HS8480!$B$2:$Y$9,MATCH("China",Raw_EU_HS8480!$A$2:$A$9,0),7)/(INDEX(Raw_EU_HS8480!$B$2:$Y$9,MATCH("Canada",Raw_EU_HS8480!$A$2:$A$9,0),7)+INDEX(Raw_EU_HS8480!$B$2:$Y$9,MATCH("China",Raw_EU_HS8480!$A$2:$A$9,0),7)+INDEX(Raw_EU_HS8480!$B$2:$Y$9,MATCH("Japan",Raw_EU_HS8480!$A$2:$A$9,0),7)+INDEX(Raw_EU_HS8480!$B$2:$Y$9,MATCH("Malaysia",Raw_EU_HS8480!$A$2:$A$9,0),7)+INDEX(Raw_EU_HS8480!$B$2:$Y$9,MATCH("Singapore",Raw_EU_HS8480!$A$2:$A$9,0),7)+INDEX(Raw_EU_HS8480!$B$2:$Y$9,MATCH("Thailand",Raw_EU_HS8480!$A$2:$A$9,0),7)+INDEX(Raw_EU_HS8480!$B$2:$Y$9,MATCH("Taiwan",Raw_EU_HS8480!$A$2:$A$9,0),7)+INDEX(Raw_EU_HS8480!$B$2:$Y$9,MATCH("Vietnam",Raw_EU_HS8480!$A$2:$A$9,0),7)) -> 0.63537817 | I6: =INDEX(Raw_EU_HS8480!$B$2:$Y$9,MATCH("China",Raw_EU_HS8480!$A$2:$A$9,0),8)/(INDEX(Raw_EU_HS8480!$B$2:$Y$9,MATCH("Canada",Raw_EU_HS8480!$A$2:$A$9,0),8)+INDEX(Raw_EU_HS8480!$B$2:$Y$9,MATCH("China",Raw_EU_HS8480!$A$2:$A$9,0),8)+INDEX(Raw_EU_HS8480!$B$2:$Y$9,MATCH("Japan",Raw_EU_HS8480!$A$2:$A$9,0),8)+INDEX(Raw_EU_HS8480!$B$2:$Y$9,MATCH("Malaysia",Raw_EU_HS8480!$A$2:$A$9,0),8)+INDEX(Raw_EU_HS8480!$B$2:$Y$9,MATCH("Singapore",Raw_EU_HS8480!$A$2:$A$9,0),8)+INDEX(Raw_EU_HS8480!$B$2:$Y$9,MATCH("Thailand",Raw_EU_HS8480!$A$2:$A$9,0),8)+INDEX(Raw_EU_HS8480!$B$2:$Y$9,MATCH("Taiwan",Raw_EU_HS8480!$A$2:$A$9,0),8)+INDEX(Raw_EU_HS8480!$B$2:$Y$9,MATCH("Vietnam",Raw_EU_HS8480!$A$2:$A$9,0),8)) -> 0.65417863 | J6: =INDEX(Raw_EU_HS8480!$B$2:$Y$9,MATCH("China",Raw_EU_HS8480!$A$2:$A$9,0),9)/(INDEX(Raw_EU_HS8480!$B$2:$Y$9,MATCH("Canada",Raw_EU_HS8480!$A$2:$A$9,0),9)+INDEX(Raw_EU_HS8480!$B$2:$Y$9,MATCH("China",Raw_EU_HS8480!$A$2:$A$9,0),9)+INDEX(Raw_EU_HS8480!$B$2:$Y$9,MATCH("Japan",Raw_EU_HS8480!$A$2:$A$9,0),9)+INDEX(Raw_EU_HS8480!$B$2:$Y$9,MATCH("Malaysia",Raw_EU_HS8480!$A$2:$A$9,0),9)+INDEX(Raw_EU_HS8480!$B$2:$Y$9,MATCH("Singapore",Raw_EU_HS8480!$A$2:$A$9,0),9)+INDEX(Raw_EU_HS8480!$B$2:$Y$9,MATCH("Thailand",Raw_EU_HS8480!$A$2:$A$9,0),9)+INDEX(Raw_EU_HS8480!$B$2:$Y$9,MATCH("Taiwan",Raw_EU_HS8480!$A$2:$A$9,0),9)+INDEX(Raw_EU_HS8480!$B$2:$Y$9,MATCH("Vietnam",Raw_EU_HS8480!$A$2:$A$9,0),9)) -> 0.68919766 | K6: =INDEX(Raw_EU_HS8480!$B$2:$Y$9,MATCH("China",Raw_EU_HS8480!$A$2:$A$9,0),10)/(INDEX(Raw_EU_HS8480!$B$2:$Y$9,MATCH("Canada",Raw_EU_HS8480!$A$2:$A$9,0),10)+INDEX(Raw_EU_HS8480!$B$2:$Y$9,MATCH("China",Raw_EU_HS8480!$A$2:$A$9,0),10)+INDEX(Raw_EU_HS8480!$B$2:$Y$9,MATCH("Japan",Raw_EU_HS8480!$A$2:$A$9,0),10)+INDEX(Raw_EU_HS8480!$B$2:$Y$9,MATCH("Malaysia",Raw_EU_HS8480!$A$2:$A$9,0),10)+INDEX(Raw_EU_HS8480!$B$2:$Y$9,MATCH("Singapore",Raw_EU_HS8480!$A$2:$A$9,0),10)+INDEX(Raw_EU_HS8480!$B$2:$Y$9,MATCH("Thailand",Raw_EU_HS8480!$A$2:$A$9,0),10)+INDEX(Raw_EU_HS8480!$B$2:$Y$9,MATCH("Taiwan",Raw_EU_HS8480!$A$2:$A$9,0),10)+INDEX(Raw_EU_HS8480!$B$2:$Y$9,MATCH("Vietnam",Raw_EU_HS8480!$A$2:$A$9,0),10)) -> 0.75545266 | L6: =INDEX(Raw_EU_HS8480!$B$2:$Y$9,MATCH("China",Raw_EU_HS8480!$A$2:$A$9,0),11)/(INDEX(Raw_EU_HS8480!$B$2:$Y$9,MATCH("Canada",Raw_EU_HS8480!$A$2:$A$9,0),11)+INDEX(Raw_EU_HS8480!$B$2:$Y$9,MATCH("China",Raw_EU_HS8480!$A$2:$A$9,0),11)+INDEX(Raw_EU_HS8480!$B$2:$Y$9,MATCH("Japan",Raw_EU_HS8480!$A$2:$A$9,0),11)+INDEX(Raw_EU_HS8480!$B$2:$Y$9,MATCH("Malaysia",Raw_EU_HS8480!$A$2:$A$9,0),11)+INDEX(Raw_EU_HS8480!$B$2:$Y$9,MATCH("Singapore",Raw_EU_HS8480!$A$2:$A$9,0),11)+INDEX(Raw_EU_HS8480!$B$2:$Y$9,MATCH("Thailand",Raw_EU_HS8480!$A$2:$A$9,0),11)+INDEX(Raw_EU_HS8480!$B$2:$Y$9,MATCH("Taiwan",Raw_EU_HS8480!$A$2:$A$9,0),11)+INDEX(Raw_EU_HS8480!$B$2:$Y$9,MATCH("Vietnam",Raw_EU_HS8480!$A$2:$A$9,0),11)) -> 0.79615769 | M6: =INDEX(Raw_EU_HS8480!$B$2:$Y$9,MATCH("China",Raw_EU_HS8480!$A$2:$A$9,0),12)/(INDEX(Raw_EU_HS8480!$B$2:$Y$9,MATCH("Canada",Raw_EU_HS8480!$A$2:$A$9,0),12)+INDEX(Raw_EU_HS8480!$B$2:$Y$9,MATCH("China",Raw_EU_HS8480!$A$2:$A$9,0),12)+INDEX(Raw_EU_HS8480!$B$2:$Y$9,MATCH("Japan",Raw_EU_HS8480!$A$2:$A$9,0),12)+INDEX(Raw_EU_HS8480!$B$2:$Y$9,MATCH("Malaysia",Raw_EU_HS8480!$A$2:$A$9,0),12)+INDEX(Raw_EU_HS8480!$B$2:$Y$9,MATCH("Singapore",Raw_EU_HS8480!$A$2:$A$9,0),12)+INDEX(Raw_EU_HS8480!$B$2:$Y$9,MATCH("Thailand",Raw_EU_HS8480!$A$2:$A$9,0),12)+INDEX(Raw_EU_HS8480!$B$2:$Y$9,MATCH("Taiwan",Raw_EU_HS8480!$A$2:$A$9,0),12)+INDEX(Raw_EU_HS8480!$B$2:$Y$9,MATCH("Vietnam",Raw_EU_HS8480!$A$2:$A$9,0),12)) -> 0.80599612 | N6: =INDEX(Raw_EU_HS8480!$B$2:$Y$9,MATCH("China",Raw_EU_HS8480!$A$2:$A$9,0),13)/(INDEX(Raw_EU_HS8480!$B$2:$Y$9,MATCH("Canada",Raw_EU_HS8480!$A$2:$A$9,0),13)+INDEX(Raw_EU_HS8480!$B$2:$Y$9,MATCH("China",Raw_EU_HS8480!$A$2:$A$9,0),13)+INDEX(Raw_EU_HS8480!$B$2:$Y$9,MATCH("Japan",Raw_EU_HS8480!$A$2:$A$9,0),13)+INDEX(Raw_EU_HS8480!$B$2:$Y$9,MATCH("Malaysia",Raw_EU_HS8480!$A$2:$A$9,0),13)+INDEX(Raw_EU_HS8480!$B$2:$Y$9,MATCH("Singapore",Raw_EU_HS8480!$A$2:$A$9,0),13)+INDEX(Raw_EU_HS8480!$B$2:$Y$9,MATCH("Thailand",Raw_EU_HS8480!$A$2:$A$9,0),13)+INDEX(Raw_EU_HS8480!$B$2:$Y$9,MATCH("Taiwan",Raw_EU_HS8480!$A$2:$A$9,0),13)+INDEX(Raw_EU_HS8480!$B$2:$Y$9,MATCH("Vietnam",Raw_EU_HS8480!$A$2:$A$9,0),13)) -> 0.82729522 | O6: =INDEX(Raw_EU_HS8480!$B$2:$Y$9,MATCH("China",Raw_EU_HS8480!$A$2:$A$9,0),14)/(INDEX(Raw_EU_HS8480!$B$2:$Y$9,MATCH("Canada",Raw_EU_HS8480!$A$2:$A$9,0),14)+INDEX(Raw_EU_HS8480!$B$2:$Y$9,MATCH("China",Raw_EU_HS8480!$A$2:$A$9,0),14)+INDEX(Raw_EU_HS8480!$B$2:$Y$9,MATCH("Japan",Raw_EU_HS8480!$A$2:$A$9,0),14)+INDEX(Raw_EU_HS8480!$B$2:$Y$9,MATCH("Malaysia",Raw_EU_HS8480!$A$2:$A$9,0),14)+INDEX(Raw_EU_HS8480!$B$2:$Y$9,MATCH("Singapore",Raw_EU_HS8480!$A$2:$A$9,0),14)+INDEX(Raw_EU_HS8480!$B$2:$Y$9,MATCH("Thailand",Raw_EU_HS8480!$A$2:$A$9,0),14)+INDEX(Raw_EU_HS8480!$B$2:$Y$9,MATCH("Taiwan",Raw_EU_HS8480!$A$2:$A$9,0),14)+INDEX(Raw_EU_HS8480!$B$2:$Y$9,MATCH("Vietnam",Raw_EU_HS8480!$A$2:$A$9,0),14)) -> 0.85166195 | P6: =INDEX(Raw_EU_HS8480!$B$2:$Y$9,MATCH("China",Raw_EU_HS8480!$A$2:$A$9,0),15)/(INDEX(Raw_EU_HS8480!$B$2:$Y$9,MATCH("Canada",Raw_EU_HS8480!$A$2:$A$9,0),15)+INDEX(Raw_EU_HS8480!$B$2:$Y$9,MATCH("China",Raw_EU_HS8480!$A$2:$A$9,0),15)+INDEX(Raw_EU_HS8480!$B$2:$Y$9,MATCH("Japan",Raw_EU_HS8480!$A$2:$A$9,0),15)+INDEX(Raw_EU_HS8480!$B$2:$Y$9,MATCH("Malaysia",Raw_EU_HS8480!$A$2:$A$9,0),15)+INDEX(Raw_EU_HS8480!$B$2:$Y$9,MATCH("Singapore",Raw_EU_HS8480!$A$2:$A$9,0),15)+INDEX(Raw_EU_HS8480!$B$2:$Y$9,MATCH("Thailand",Raw_EU_HS8480!$A$2:$A$9,0),15)+INDEX(Raw_EU_HS8480!$B$2:$Y$9,MATCH("Taiwan",Raw_EU_HS8480!$A$2:$A$9,0),15)+INDEX(Raw_EU_HS8480!$B$2:$Y$9,MATCH("Vietnam",Raw_EU_HS8480!$A$2:$A$9,0),15)) -> 0.85132382 | Q6: =INDEX(Raw_EU_HS8480!$B$2:$Y$9,MATCH("China",Raw_EU_HS8480!$A$2:$A$9,0),16)/(INDEX(Raw_EU_HS8480!$B$2:$Y$9,MATCH("Canada",Raw_EU_HS8480!$A$2:$A$9,0),16)+INDEX(Raw_EU_HS8480!$B$2:$Y$9,MATCH("China",Raw_EU_HS8480!$A$2:$A$9,0),16)+INDEX(Raw_EU_HS8480!$B$2:$Y$9,MATCH("Japan",Raw_EU_HS8480!$A$2:$A$9,0),16)+INDEX(Raw_EU_HS8480!$B$2:$Y$9,MATCH("Malaysia",Raw_EU_HS8480!$A$2:$A$9,0),16)+INDEX(Raw_EU_HS8480!$B$2:$Y$9,MATCH("Singapore",Raw_EU_HS8480!$A$2:$A$9,0),16)+INDEX(Raw_EU_HS8480!$B$2:$Y$9,MATCH("Thailand",Raw_EU_HS8480!$A$2:$A$9,0),16)+INDEX(Raw_EU_HS8480!$B$2:$Y$9,MATCH("Taiwan",Raw_EU_HS8480!$A$2:$A$9,0),16)+INDEX(Raw_EU_HS8480!$B$2:$Y$9,MATCH("Vietnam",Raw_EU_HS8480!$A$2:$A$9,0),16)) -> 0.86873291 | R6: =INDEX(Raw_EU_HS8480!$B$2:$Y$9,MATCH("China",Raw_EU_HS8480!$A$2:$A$9,0),17)/(INDEX(Raw_EU_HS8480!$B$2:$Y$9,MATCH("Canada",Raw_EU_HS8480!$A$2:$A$9,0),17)+INDEX(Raw_EU_HS8480!$B$2:$Y$9,MATCH("China",Raw_EU_HS8480!$A$2:$A$9,0),17)+INDEX(Raw_EU_HS8480!$B$2:$Y$9,MATCH("Japan",Raw_EU_HS8480!$A$2:$A$9,0),17)+INDEX(Raw_EU_HS8480!$B$2:$Y$9,MATCH("Malaysia",Raw_EU_HS8480!$A$2:$A$9,0),17)+INDEX(Raw_EU_HS8480!$B$2:$Y$9,MATCH("Singapore",Raw_EU_HS8480!$A$2:$A$9,0),17)+INDEX(Raw_EU_HS8480!$B$2:$Y$9,MATCH("Thailand",Raw_EU_HS8480!$A$2:$A$9,0),17)+INDEX(Raw_EU_HS8480!$B$2:$Y$9,MATCH("Taiwan",Raw_EU_HS8480!$A$2:$A$9,0),17)+INDEX(Raw_EU_HS8480!$B$2:$Y$9,MATCH("Vietnam",Raw_EU_HS8480!$A$2:$A$9,0),17)) -> 0.88305341 | S6: =INDEX(Raw_EU_HS8480!$B$2:$Y$9,MATCH("China",Raw_EU_HS8480!$A$2:$A$9,0),18)/(INDEX(Raw_EU_HS8480!$B$2:$Y$9,MATCH("Canada",Raw_EU_HS8480!$A$2:$A$9,0),18)+INDEX(Raw_EU_HS8480!$B$2:$Y$9,MATCH("China",Raw_EU_HS8480!$A$2:$A$9,0),18)+INDEX(Raw_EU_HS8480!$B$2:$Y$9,MATCH("Japan",Raw_EU_HS8480!$A$2:$A$9,0),18)+INDEX(Raw_EU_HS8480!$B$2:$Y$9,MATCH("Malaysia",Raw_EU_HS8480!$A$2:$A$9,0),18)+INDEX(Raw_EU_HS8480!$B$2:$Y$9,MATCH("Singapore",Raw_EU_HS8480!$A$2:$A$9,0),18)+INDEX(Raw_EU_HS8480!$B$2:$Y$9,MATCH("Thailand",Raw_EU_HS8480!$A$2:$A$9,0),18)+INDEX(Raw_EU_HS8480!$B$2:$Y$9,MATCH("Taiwan",Raw_EU_HS8480!$A$2:$A$9,0),18)+INDEX(Raw_EU_HS8480!$B$2:$Y$9,MATCH("Vietnam",Raw_EU_HS8480!$A$2:$A$9,0),18)) -> 0.88791459 | T6: =INDEX(Raw_EU_HS8480!$B$2:$Y$9,MATCH("China",Raw_EU_HS8480!$A$2:$A$9,0),19)/(INDEX(Raw_EU_HS8480!$B$2:$Y$9,MATCH("Canada",Raw_EU_HS8480!$A$2:$A$9,0),19)+INDEX(Raw_EU_HS8480!$B$2:$Y$9,MATCH("China",Raw_EU_HS8480!$A$2:$A$9,0),19)+INDEX(Raw_EU_HS8480!$B$2:$Y$9,MATCH("Japan",Raw_EU_HS8480!$A$2:$A$9,0),19)+INDEX(Raw_EU_HS8480!$B$2:$Y$9,MATCH("Malaysia",Raw_EU_HS8480!$A$2:$A$9,0),19)+INDEX(Raw_EU_HS8480!$B$2:$Y$9,MATCH("Singapore",Raw_EU_HS8480!$A$2:$A$9,0),19)+INDEX(Raw_EU_HS8480!$B$2:$Y$9,MATCH("Thailand",Raw_EU_HS8480!$A$2:$A$9,0),19)+INDEX(Raw_EU_HS8480!$B$2:$Y$9,MATCH("Taiwan",Raw_EU_HS8480!$A$2:$A$9,0),19)+INDEX(Raw_EU_HS8480!$B$2:$Y$9,MATCH("Vietnam",Raw_EU_HS8480!$A$2:$A$9,0),19)) -> 0.89813892 | U6: =INDEX(Raw_EU_HS8480!$B$2:$Y$9,MATCH("China",Raw_EU_HS8480!$A$2:$A$9,0),20)/(INDEX(Raw_EU_HS8480!$B$2:$Y$9,MATCH("Canada",Raw_EU_HS8480!$A$2:$A$9,0),20)+INDEX(Raw_EU_HS8480!$B$2:$Y$9,MATCH("China",Raw_EU_HS8480!$A$2:$A$9,0),20)+INDEX(Raw_EU_HS8480!$B$2:$Y$9,MATCH("Japan",Raw_EU_HS8480!$A$2:$A$9,0),20)+INDEX(Raw_EU_HS8480!$B$2:$Y$9,MATCH("Malaysia",Raw_EU_HS8480!$A$2:$A$9,0),20)+INDEX(Raw_EU_HS8480!$B$2:$Y$9,MATCH("Singapore",Raw_EU_HS8480!$A$2:$A$9,0),20)+INDEX(Raw_EU_HS8480!$B$2:$Y$9,MATCH("Thailand",Raw_EU_HS8480!$A$2:$A$9,0),20)+INDEX(Raw_EU_HS8480!$B$2:$Y$9,MATCH("Taiwan",Raw_EU_HS8480!$A$2:$A$9,0),20)+INDEX(Raw_EU_HS8480!$B$2:$Y$9,MATCH("Vietnam",Raw_EU_HS8480!$A$2:$A$9,0),20)) -> 0.89324276 | V6: =INDEX(Raw_EU_HS8480!$B$2:$Y$9,MATCH("China",Raw_EU_HS8480!$A$2:$A$9,0),21)/(INDEX(Raw_EU_HS8480!$B$2:$Y$9,MATCH("Canada",Raw_EU_HS8480!$A$2:$A$9,0),21)+INDEX(Raw_EU_HS8480!$B$2:$Y$9,MATCH("China",Raw_EU_HS8480!$A$2:$A$9,0),21)+INDEX(Raw_EU_HS8480!$B$2:$Y$9,MATCH("Japan",Raw_EU_HS8480!$A$2:$A$9,0),21)+INDEX(Raw_EU_HS8480!$B$2:$Y$9,MATCH("Malaysia",Raw_EU_HS8480!$A$2:$A$9,0),21)+INDEX(Raw_EU_HS8480!$B$2:$Y$9,MATCH("Singapore",Raw_EU_HS8480!$A$2:$A$9,0),21)+INDEX(Raw_EU_HS8480!$B$2:$Y$9,MATCH("Thailand",Raw_EU_HS8480!$A$2:$A$9,0),21)+INDEX(Raw_EU_HS8480!$B$2:$Y$9,MATCH("Taiwan",Raw_EU_HS8480!$A$2:$A$9,0),21)+INDEX(Raw_EU_HS8480!$B$2:$Y$9,MATCH("Vietnam",Raw_EU_HS8480!$A$2:$A$9,0),21)) -> 0.90562356 | W6: =INDEX(Raw_EU_HS8480!$B$2:$Y$9,MATCH("China",Raw_EU_HS8480!$A$2:$A$9,0),22)/(INDEX(Raw_EU_HS8480!$B$2:$Y$9,MATCH("Canada",Raw_EU_HS8480!$A$2:$A$9,0),22)+INDEX(Raw_EU_HS8480!$B$2:$Y$9,MATCH("China",Raw_EU_HS8480!$A$2:$A$9,0),22)+INDEX(Raw_EU_HS8480!$B$2:$Y$9,MATCH("Japan",Raw_EU_HS8480!$A$2:$A$9,0),22)+INDEX(Raw_EU_HS8480!$B$2:$Y$9,MATCH("Malaysia",Raw_EU_HS8480!$A$2:$A$9,0),22)+INDEX(Raw_EU_HS8480!$B$2:$Y$9,MATCH("Singapore",Raw_EU_HS8480!$A$2:$A$9,0),22)+INDEX(Raw_EU_HS8480!$B$2:$Y$9,MATCH("Thailand",Raw_EU_HS8480!$A$2:$A$9,0),22)+INDEX(Raw_EU_HS8480!$B$2:$Y$9,MATCH("Taiwan",Raw_EU_HS8480!$A$2:$A$9,0),22)+INDEX(Raw_EU_HS8480!$B$2:$Y$9,MATCH("Vietnam",Raw_EU_HS8480!$A$2:$A$9,0),22)) -> 0.92221297 | X6: =INDEX(Raw_EU_HS8480!$B$2:$Y$9,MATCH("China",Raw_EU_HS8480!$A$2:$A$9,0),23)/(INDEX(Raw_EU_HS8480!$B$2:$Y$9,MATCH("Canada",Raw_EU_HS8480!$A$2:$A$9,0),23)+INDEX(Raw_EU_HS8480!$B$2:$Y$9,MATCH("China",Raw_EU_HS8480!$A$2:$A$9,0),23)+INDEX(Raw_EU_HS8480!$B$2:$Y$9,MATCH("Japan",Raw_EU_HS8480!$A$2:$A$9,0),23)+INDEX(Raw_EU_HS8480!$B$2:$Y$9,MATCH("Malaysia",Raw_EU_HS8480!$A$2:$A$9,0),23)+INDEX(Raw_EU_HS8480!$B$2:$Y$9,MATCH("Singapore",Raw_EU_HS8480!$A$2:$A$9,0),23)+INDEX(Raw_EU_HS8480!$B$2:$Y$9,MATCH("Thailand",Raw_EU_HS8480!$A$2:$A$9,0),23)+INDEX(Raw_EU_HS8480!$B$2:$Y$9,MATCH("Taiwan",Raw_EU_HS8480!$A$2:$A$9,0),23)+INDEX(Raw_EU_HS8480!$B$2:$Y$9,MATCH("Vietnam",Raw_EU_HS8480!$A$2:$A$9,0),23)) -> 0.92438524 | Y6: =INDEX(Raw_EU_HS8480!$B$2:$Y$9,MATCH("China",Raw_EU_HS8480!$A$2:$A$9,0),24)/(INDEX(Raw_EU_HS8480!$B$2:$Y$9,MATCH("Canada",Raw_EU_HS8480!$A$2:$A$9,0),24)+INDEX(Raw_EU_HS8480!$B$2:$Y$9,MATCH("China",Raw_EU_HS8480!$A$2:$A$9,0),24)+INDEX(Raw_EU_HS8480!$B$2:$Y$9,MATCH("Japan",Raw_EU_HS8480!$A$2:$A$9,0),24)+INDEX(Raw_EU_HS8480!$B$2:$Y$9,MATCH("Malaysia",Raw_EU_HS8480!$A$2:$A$9,0),24)+INDEX(Raw_EU_HS8480!$B$2:$Y$9,MATCH("Singapore",Raw_EU_HS8480!$A$2:$A$9,0),24)+INDEX(Raw_EU_HS8480!$B$2:$Y$9,MATCH("Thailand",Raw_EU_HS8480!$A$2:$A$9,0),24)+INDEX(Raw_EU_HS8480!$B$2:$Y$9,MATCH("Taiwan",Raw_EU_HS8480!$A$2:$A$9,0),24)+INDEX(Raw_EU_HS8480!$B$2:$Y$9,MATCH("Vietnam",Raw_EU_HS8480!$A$2:$A$9,0),24)) -> 0.93637597
